<?xml version="1.0" encoding="UTF-8"?>
<testng-results ignored="0" total="3" passed="1" failed="1" skipped="1">
  <reporter-output>
  </reporter-output>
  <suite started-at="2025-03-10T21:06:42 IST" name="Suite" finished-at="2025-03-10T21:06:42 IST" duration-ms="159">
    <groups>
    </groups>
    <test started-at="2025-03-10T21:06:42 IST" name="Test" finished-at="2025-03-10T21:06:42 IST" duration-ms="159">
      <class name="demo.TestCase">
        <test-method signature="TestOne()[pri:0, instance:demo.TestCase@15bb5034]" started-at="2025-03-10T21:06:42 IST" name="TestOne" finished-at="2025-03-10T21:06:42 IST" duration-ms="13" status="PASS">
          <reporter-output>
          </reporter-output>
        </test-method> <!-- TestOne -->
        <test-method signature="TestTwo()[pri:0, instance:demo.TestCase@15bb5034]" started-at="2025-03-10T21:06:42 IST" name="TestTwo" finished-at="2025-03-10T21:06:42 IST" duration-ms="20" status="FAIL">
          <exception class="java.lang.AssertionError">
            <message>
              <![CDATA[expected [false] but found [true]]]>
            </message>
            <full-stacktrace>
              <![CDATA[java.lang.AssertionError: expected [false] but found [true]
at org.testng.Assert.fail(Assert.java:111)
at org.testng.Assert.failNotEquals(Assert.java:1578)
at org.testng.Assert.assertFalse(Assert.java:79)
at org.testng.Assert.assertFalse(Assert.java:89)
at demo.TestCase.TestTwo(TestCase.java:18)
at java.base/jdk.internal.reflect.NativeMethodAccessorImpl.invoke0(Native Method)
at java.base/jdk.internal.reflect.NativeMethodAccessorImpl.invoke(NativeMethodAccessorImpl.java:77)
at java.base/jdk.internal.reflect.DelegatingMethodAccessorImpl.invoke(DelegatingMethodAccessorImpl.java:43)
at java.base/java.lang.reflect.Method.invoke(Method.java:568)
at org.testng.internal.invokers.MethodInvocationHelper.invokeMethod(MethodInvocationHelper.java:141)
at org.testng.internal.invokers.TestInvoker.invokeMethod(TestInvoker.java:686)
at org.testng.internal.invokers.TestInvoker.invokeTestMethod(TestInvoker.java:230)
at org.testng.internal.invokers.MethodRunner.runInSequence(MethodRunner.java:63)
at org.testng.internal.invokers.TestInvoker$MethodInvocationAgent.invoke(TestInvoker.java:992)
at org.testng.internal.invokers.TestInvoker.invokeTestMethods(TestInvoker.java:203)
at org.testng.internal.invokers.TestMethodWorker.invokeTestMethods(TestMethodWorker.java:154)
at org.testng.internal.invokers.TestMethodWorker.run(TestMethodWorker.java:134)
at java.base/java.util.ArrayList.forEach(ArrayList.java:1511)
at org.testng.TestRunner.privateRun(TestRunner.java:739)
at org.testng.TestRunner.run(TestRunner.java:614)
at org.testng.SuiteRunner.runTest(SuiteRunner.java:421)
at org.testng.SuiteRunner.runSequentially(SuiteRunner.java:413)
at org.testng.SuiteRunner.privateRun(SuiteRunner.java:373)
at org.testng.SuiteRunner.run(SuiteRunner.java:312)
at org.testng.SuiteRunnerWorker.runSuite(SuiteRunnerWorker.java:52)
at org.testng.SuiteRunnerWorker.run(SuiteRunnerWorker.java:95)
at org.testng.TestNG.runSuitesSequentially(TestNG.java:1274)
at org.testng.TestNG.runSuitesLocally(TestNG.java:1208)
at org.testng.TestNG.runSuites(TestNG.java:1112)
at org.testng.TestNG.run(TestNG.java:1079)
at org.testng.remote.AbstractRemoteTestNG.run(AbstractRemoteTestNG.java:115)
at org.testng.remote.RemoteTestNG.initAndRun(RemoteTestNG.java:293)
at org.testng.remote.RemoteTestNG.main(RemoteTestNG.java:91)
]]>
            </full-stacktrace>
          </exception> <!-- java.lang.AssertionError -->
          <reporter-output>
          </reporter-output>
        </test-method> <!-- TestTwo -->
        <test-method signature="Testthree()[pri:0, instance:demo.TestCase@15bb5034]" started-at="2025-03-10T21:06:42 IST" name="Testthree" finished-at="2025-03-10T21:06:42 IST" depends-on-methods="demo.TestCase.TestTwo" duration-ms="0" status="SKIP">
          <exception class="java.lang.Throwable">
            <message>
              <![CDATA[Method demo.TestCase.Testthree() on instance demo.TestCase@15bb5034 depends on not successfully finished methods 
[demo.TestCase.TestTwo() on instance demo.TestCase@15bb5034]]]>
            </message>
            <full-stacktrace>
              <![CDATA[java.lang.Throwable: Method demo.TestCase.Testthree() on instance demo.TestCase@15bb5034 depends on not successfully finished methods 
[demo.TestCase.TestTwo() on instance demo.TestCase@15bb5034]
at org.testng.internal.invokers.TestInvoker.invokeTestMethods(TestInvoker.java:159)
at org.testng.internal.invokers.TestMethodWorker.invokeTestMethods(TestMethodWorker.java:154)
at org.testng.internal.invokers.TestMethodWorker.run(TestMethodWorker.java:134)
at java.base/java.util.ArrayList.forEach(ArrayList.java:1511)
at org.testng.TestRunner.privateRun(TestRunner.java:739)
at org.testng.TestRunner.run(TestRunner.java:614)
at org.testng.SuiteRunner.runTest(SuiteRunner.java:421)
at org.testng.SuiteRunner.runSequentially(SuiteRunner.java:413)
at org.testng.SuiteRunner.privateRun(SuiteRunner.java:373)
at org.testng.SuiteRunner.run(SuiteRunner.java:312)
at org.testng.SuiteRunnerWorker.runSuite(SuiteRunnerWorker.java:52)
at org.testng.SuiteRunnerWorker.run(SuiteRunnerWorker.java:95)
at org.testng.TestNG.runSuitesSequentially(TestNG.java:1274)
at org.testng.TestNG.runSuitesLocally(TestNG.java:1208)
at org.testng.TestNG.runSuites(TestNG.java:1112)
at org.testng.TestNG.run(TestNG.java:1079)
at org.testng.remote.AbstractRemoteTestNG.run(AbstractRemoteTestNG.java:115)
at org.testng.remote.RemoteTestNG.initAndRun(RemoteTestNG.java:293)
at org.testng.remote.RemoteTestNG.main(RemoteTestNG.java:91)
]]>
            </full-stacktrace>
          </exception> <!-- java.lang.Throwable -->
          <reporter-output>
          </reporter-output>
        </test-method> <!-- Testthree -->
      </class> <!-- demo.TestCase -->
    </test> <!-- Test -->
  </suite> <!-- Suite -->
</testng-results>
